Workbook

Sheet Berat
A2: Tabel Valuasi Tonase | G2: Dibuat Oleh | H2: Diperiksa Oleh | I2: Diterima Oleh
A3: No | B3: Deskripsi | C3: Kg | G3: Staff Engineer | H3: Supervisor Project | I3: Head Workshop
A4: I | B4: Tonase Bersih | C4: ='P1-DSR'!H24+'J1-DSR'!H23+'J2-DSR'!H23+'J2-01'!H20 -> 65.328215
A5: II | B5: Tonase Kotor | C5: =KOP!F37 -> 102.103
A6: III | B6: Tonase Waste | C6: =C5-C4 -> 36.774785
A7: TGL FABRIKASI | C7: Mulai :
C8: Selesai :

Sheet LOGO
C2: WORK ORDER | D2: No WO | E2: : 01/WO/IV/26 | F2: Form No. | G2: FR-EG-11
D3: Proyek | E3: : ASTERA ( MOCKUP TERPASANG ) | F3: Rev | G3: 0
D4: Jenis / Warna | E4: : SF-100 / YB1N | F4: Date | G4: 44835

Sheet Form Ukur Kaca
C1: PENGUKURAN KACA | N1: Form No. | O1: FR-EG-20
N2: Rev | O2: 1
N3: Date | O3: 45369
B5: Nomor | C5: : 001.ENG/GLASS/IV/26 | N5: *PT / Pribadi
B6: Tanggal | C6: : 01 APRIL 2026 | N6: (*lingkari salah satu)
B7: Proyek | C7: =LOGO!E3 -> : ASTERA ( MOCKUP TERPASANG )
B8: Alamat Kirim | C8: :
B9: PIC Proyek | C9: : RAYA
A11: No | B11: Unit | C11: Kode Kaca | D11: Tebal Kaca (mm) | E11: Ukuran Rong | G11: Lup Lebar (mm) | H11: Lup Tinggi (mm) | I11: Ukuran Kaca | K11: Qty | L11: Qty KSN | M11: Qty TTL | N11: Total Luas (m2) | O11: Catatan
E12: Lebar (mm) | F12: Tinggi (mm) | I12: Lebar (mm) | J12: Tinggi (mm)
A13: 1 | B13: ='P1-DSR'!B66 -> P1-DSR_A2 STD_DR | C13: FLT | D13: 8 | E13: ='P1-DSR'!C17 -> 585 | F13: ='P1-DSR'!C12 -> 2150 | G13: 12 | H13: 12 | I13: =E13+G13 -> 597 | J13: =F13+H13 -> 2162 | K13: 2 | L13: 1 | M13: =L13*K13 -> 2 | N13: =(M13*J13*I13)/1000000 -> 2.581428
A14: 2 | B14: ='P1-DSR'!B67 -> P1-DSR_A2 STD_FIX | C14: FLT | D14: 8 | E14: ='P1-DSR'!C15 -> 1510 | F14: ='P1-DSR'!C9 -> 755 | G14: 12 | H14: 12 | I14: =E14+G14 -> 1522 | J14: =F14+H14 -> 767 | K14: 1 | L14: 1 | M14: =L14*K14 -> 1 | N14: =(M14*J14*I14)/1000000 -> 1.167374
A15: 3 | B15: ='J1-DSR'!B54 -> J1-DSR_A2 STD_FIX.A | C15: FLT | D15: 6 | E15: =('J1-DSR'!C12-36-8+14)/2 -> 525 | F15: ='J1-DSR'!C8-36 -> 719 | H15: 14 | I15: =E15+G15 -> 525 | J15: =F15+H15 -> 733 | K15: 2 | L15: 1 | M15: =L15*K15 -> 2 | N15: =(M15*J15*I15)/1000000 -> 0.76965
A16: 4 | B16: ='J1-DSR'!B55 -> J1-DSR_A2 STD_FIX.B | C16: FLT | D16: 6 | E16: =E15 -> 525 | F16: ='J1-DSR'!C9-36 -> 1979 | H16: 14 | I16: =E16+G16 -> 525 | J16: =F16+H16 -> 1993 | K16: 2 | L16: 1 | M16: =L16*K16 -> 2 | N16: =(M16*J16*I16)/1000000 -> 2.09265
A17: 5 | B17: ='J2-DSR'!B54 -> J2-DSR_A2 STD_FIX.A | C17: FLT | D17: 6 | E17: ='J2-DSR'!C12-36 -> 444 | F17: ='J2-DSR'!C8-36 -> 719 | G17: 14 | H17: 14 | I17: =E17+G17 -> 458 | J17: =F17+H17 -> 733 | K17: 1 | L17: 1 | M17: =L17*K17 -> 1 | N17: =(M17*J17*I17)/1000000 -> 0.335714
A18: 6 | B18: ='J2-DSR'!B55 -> J2-DSR_A2 STD_FIX.B | C18: FLT | D18: 6 | E18: =E17 -> 444 | F18: ='J2-DSR'!C9-36 -> 1979 | G18: 14 | H18: 14 | I18: =E18+G18 -> 458 | J18: =F18+H18 -> 1993 | K18: 1 | L18: 1 | M18: =L18*K18 -> 1 | N18: =(M18*J18*I18)/1000000 -> 0.912794
A19: 7 | B19: ='J2-01'!B57 -> J2-01_A2 STD_TH | C19: LGHS | D19: 8 | E19: ='J2-01'!C17 -> 702 | F19: ='J2-01'!C11 -> 1527 | G19: 12 | H19: 12 | I19: =E19+G19 -> 714 | J19: =F19+H19 -> 1539 | K19: 1 | L19: 2 | M19: =L19*K19 -> 2 | N19: =(M19*J19*I19)/1000000 -> 2.197692
A20: 8 | B20: ='J2-01'!B58 -> J2-01_A2 STD_FIX.A1 | C20: LGHS | D20: 6 | E20: ='J2-01'!C15-36 -> 764 | F20: ='J2-01'!C8-36 -> 324 | G20: 14 | H20: 14 | I20: =E20+G20 -> 778 | J20: =F20+H20 -> 338 | K20: 1 | L20: 2 | M20: =L20*K20 -> 2 | N20: =(M20*J20*I20)/1000000 -> 0.525928
A21: 9 | B21: ='J2-01'!B59 -> J2-01_A2 STD_FIX.A2 | C21: LGHS | D21: 6 | E21: ='J2-01'!C14-36 -> 1474 | F21: =F20 -> 324 | G21: 14 | H21: 14 | I21: =E21+G21 -> 1488 | J21: =F21+H21 -> 338 | K21: 1 | L21: 2 | M21: =L21*K21 -> 2 | N21: =(M21*J21*I21)/1000000 -> 1.005888
A22: 10 | B22: ='J2-01'!B60 -> J2-01_A2 STD_FIX.B | C22: LGHS | D22: 8 | E22: =('J2-01'!C14-36-8+12)/2 -> 739 | F22: ='J2-01'!C9-36 -> 1589 | H22: 12 | I22: =E22+G22 -> 739 | J22: =F22+H22 -> 1601 | K22: 2 | L22: 2 | M22: =L22*K22 -> 4 | N22: =(M22*J22*I22)/1000000 -> 4.732556
A23: 11
A24: 12
A25: 13
A26: 14
A27: 15
A28: 16
N30: =SUM(N13:N29) -> 16.321674
A34: Jenis Kaca | C34: Warna | D34: Kode | E34: Note:
A35: Clear | C35: Clear | D35: FL | E35: 1. Kode hanya digunakan untuk Kaca Non Tempered
A36: Tinted | C36: Dark Grey | D36: DG | E36: 2. Untuk Kaca Tempered, kode ditambahkan huruf "T"
C37: Dark Blue | D37: DH | E37: Contoh : Clear Tempered = FLT
C38: Euro Grey | D38: GE | E38: 3. Untuk Kaca Heat Strengthen, kode ditambahkan huruf "HS"
C39: Bronze | D39: BR | E39: Contoh : Clear Heat Strengthen = FLHS
C40: Green | D40: GN
C41: Blue Green | D41: BN
A42: Indofigure | C42: Esmislite | D42: FM
A43: Mirror | C43: Mirror | D43: MR
A44: Stopsol | C44: Dark Blue | D44: SSDH/SSDHS/CHD
C45: Euro Grey | D45: SSGE
C46: Green | D46: SSGN/CGN
...

Sheet ORDER KACA
D1: PENGUKURAN KACA | I1: Form No. | J1: FR-EG-20
I2: Rev | J2: 1
I3: Date | J3: 45369
C5: Nomor | D5: ='Form Ukur Kaca'!C5 -> : 001.ENG/GLASS/IV/26 | J5: *PT / Pribadi
C6: Tanggal | D6: ='Form Ukur Kaca'!C6 -> : 01 APRIL 2026 | J6: (*lingkari salah satu)
C7: Proyek | D7: ='Form Ukur Kaca'!C7 -> : ASTERA ( MOCKUP TERPASANG )
C8: Alamat Kirim | D8: ='Form Ukur Kaca'!C8 -> :
C9: PIC Proyek | D9: ='Form Ukur Kaca'!C9 -> : RAYA
B11: No | C11: Unit | D11: Kode Kaca | E11: Tebal Kaca (mm) | F11: Ukuran Kaca | H11: Qty | I11: Total Luas (m2) | J11: Catatan
F12: Lebar (mm) | G12: Tinggi (mm)
B13: 1 | C13: ='Form Ukur Kaca'!B13 -> P1-DSR_A2 STD_DR | D13: ='Form Ukur Kaca'!C13 -> FLT | E13: ='Form Ukur Kaca'!D13 -> 8 | F13: ='Form Ukur Kaca'!I13 -> 597 | G13: ='Form Ukur Kaca'!J13 -> 2162 | H13: ='Form Ukur Kaca'!M13 -> 2 | I13: ='Form Ukur Kaca'!N13 -> 2.581428
B14: 2 | C14: ='Form Ukur Kaca'!B14 -> P1-DSR_A2 STD_FIX | D14: ='Form Ukur Kaca'!C14 -> FLT | E14: ='Form Ukur Kaca'!D14 -> 8 | F14: ='Form Ukur Kaca'!I14 -> 1522 | G14: ='Form Ukur Kaca'!J14 -> 767 | H14: ='Form Ukur Kaca'!M14 -> 1 | I14: ='Form Ukur Kaca'!N14 -> 1.167374
B15: 3 | C15: ='Form Ukur Kaca'!B15 -> J1-DSR_A2 STD_FIX.A | D15: ='Form Ukur Kaca'!C15 -> FLT | E15: ='Form Ukur Kaca'!D15 -> 6 | F15: ='Form Ukur Kaca'!I15 -> 525 | G15: ='Form Ukur Kaca'!J15 -> 733 | H15: ='Form Ukur Kaca'!M15 -> 2 | I15: ='Form Ukur Kaca'!N15 -> 0.76965
B16: 4 | C16: ='Form Ukur Kaca'!B16 -> J1-DSR_A2 STD_FIX.B | D16: ='Form Ukur Kaca'!C16 -> FLT | E16: ='Form Ukur Kaca'!D16 -> 6 | F16: ='Form Ukur Kaca'!I16 -> 525 | G16: ='Form Ukur Kaca'!J16 -> 1993 | H16: ='Form Ukur Kaca'!M16 -> 2 | I16: ='Form Ukur Kaca'!N16 -> 2.09265
B17: 5 | C17: ='Form Ukur Kaca'!B17 -> J2-DSR_A2 STD_FIX.A | D17: ='Form Ukur Kaca'!C17 -> FLT | E17: ='Form Ukur Kaca'!D17 -> 6 | F17: ='Form Ukur Kaca'!I17 -> 458 | G17: ='Form Ukur Kaca'!J17 -> 733 | H17: ='Form Ukur Kaca'!M17 -> 1 | I17: ='Form Ukur Kaca'!N17 -> 0.335714
B18: 6 | C18: ='Form Ukur Kaca'!B18 -> J2-DSR_A2 STD_FIX.B | D18: ='Form Ukur Kaca'!C18 -> FLT | E18: ='Form Ukur Kaca'!D18 -> 6 | F18: ='Form Ukur Kaca'!I18 -> 458 | G18: ='Form Ukur Kaca'!J18 -> 1993 | H18: ='Form Ukur Kaca'!M18 -> 1 | I18: ='Form Ukur Kaca'!N18 -> 0.912794
B19: 7 | C19: ='Form Ukur Kaca'!B19 -> J2-01_A2 STD_TH | D19: ='Form Ukur Kaca'!C19 -> LGHS | E19: ='Form Ukur Kaca'!D19 -> 8 | F19: ='Form Ukur Kaca'!I19 -> 714 | G19: ='Form Ukur Kaca'!J19 -> 1539 | H19: ='Form Ukur Kaca'!M19 -> 2 | I19: ='Form Ukur Kaca'!N19 -> 2.197692
B20: 8 | C20: ='Form Ukur Kaca'!B20 -> J2-01_A2 STD_FIX.A1 | D20: ='Form Ukur Kaca'!C20 -> LGHS | E20: ='Form Ukur Kaca'!D20 -> 6 | F20: ='Form Ukur Kaca'!I20 -> 778 | G20: ='Form Ukur Kaca'!J20 -> 338 | H20: ='Form Ukur Kaca'!M20 -> 2 | I20: ='Form Ukur Kaca'!N20 -> 0.525928
B21: 9 | C21: ='Form Ukur Kaca'!B21 -> J2-01_A2 STD_FIX.A2 | D21: ='Form Ukur Kaca'!C21 -> LGHS | E21: ='Form Ukur Kaca'!D21 -> 6 | F21: ='Form Ukur Kaca'!I21 -> 1488 | G21: ='Form Ukur Kaca'!J21 -> 338 | H21: ='Form Ukur Kaca'!M21 -> 2 | I21: ='Form Ukur Kaca'!N21 -> 1.005888
B22: 10 | C22: ='Form Ukur Kaca'!B22 -> J2-01_A2 STD_FIX.B | D22: ='Form Ukur Kaca'!C22 -> LGHS | E22: ='Form Ukur Kaca'!D22 -> 8 | F22: ='Form Ukur Kaca'!I22 -> 739 | G22: ='Form Ukur Kaca'!J22 -> 1601 | H22: ='Form Ukur Kaca'!M22 -> 4 | I22: ='Form Ukur Kaca'!N22 -> 4.732556
L23: =#REF!+'J1-DSR'!E54+'J1-DSR'!#REF!+'J1-DSR'!#REF!+#REF!+#REF!+#REF!+#REF!+#REF!+#REF!+#REF!+#REF!+#REF!+#REF!+#REF!+#REF! -> #REF!
C24: TOTAL | H24: =SUM(H13:H23) -> 19 | I24: =SUM(I13:I23) -> 16.321674
B27: Jenis Kaca | D27: Warna | E27: Kode | F27: Note:
B28: Clear | D28: Clear | E28: FL | F28: 1. Kode hanya digunakan untuk Kaca Non Tempered
B29: Tinted | D29: Dark Grey | E29: DG | F29: 2. Untuk Kaca Tempered, kode ditambahkan huruf "T"
D30: Dark Blue | E30: DH | F30: Contoh : Clear Tempered = FLT
D31: Euro Grey | E31: GE | F31: 3. Untuk Kaca Heat Strengthen, kode ditambahkan huruf "HS"
D32: Bronze | E32: BR | F32: Contoh : Clear Heat Strengthen = FLHS
D33: Green | E33: GN
D34: Blue Green | E34: BN
D35: Lite Grey | E35: LG
B36: Indofigure | D36: Esmislite | E36: FM
B37: Mirror | D37: Mirror | E37: MR
B38: Stopsol | D38: Dark Blue | E38: SSDH/SSDHS/CHD
D39: Euro Grey | E39: SSGE
D40: Green | E40: SSGN/CGN
D41: Blue Green | E41: SSBN
B42: Sunergy / Low-E | D42: Clear | E42: SNFL
C44: Dibuat Oleh, | G44: Disetujui Oleh, | J44: Diterima Oleh,
C45: Staff Engineer | G45: Supervisor Project | J45: Staff PPIC
...

Sheet KOP
A5: Tanggal WO | B5: ='ORDER KACA'!D6 -> : 01 APRIL 2026
A6: No. WO | B6: =LOGO!E2 -> : 01/WO/IV/26
A7: Proyek | B7: =LOGO!E3 -> : ASTERA ( MOCKUP TERPASANG )
A8: Jenis/Warna | B8: =LOGO!E4 -> : SF-100 / YB1N
A9: Type | B9: : A2 STD
A10: Tangga | B10: : Kanan
A11: Nama Departemen | B11: : RAT-SBU-26002
A13: ITEM/UNIT | B13: WARNA | C13: QTY | D13: KETERANGAN
A14: P1-DSR_A2 STD | B14: YB1N | C14: 1
A15: J1-DSR_A2 STD | B15: YB1N | C15: 1
A16: J2-DSR_A2 STD | B16: YB1N | C16: 1
A17: J2-01_A2 STD | B17: YB1N | C17: 2
A18: TOTAL | C18: =SUM(C14:C17) -> 5
A19: KEBUTUHAN MATERIAL
A20: KODE | B20: PANJANG | C20: QTY | D20: KETERANGAN
A21: =Sheet4!T4 -> 9K-86001 | B21: =Sheet4!U4 -> 6000 | C21: =Sheet4!V4 -> 2 | E21: =VLOOKUP(A21,[1]Sheet3!$A:$E,3,0) -> 0.948 | F21: =E21*C21*B21/1000 -> 11.376
A22: =Sheet4!T5 -> 9K-86007 | B22: =Sheet4!U5 -> 6000 | C22: =Sheet4!V5 -> 1 | E22: =VLOOKUP(A22,[1]Sheet3!$A:$E,3,0) -> 0.458 | F22: =E22*C22*B22/1000 -> 2.748
A23: =Sheet4!T6 -> 9K-86005 | B23: =Sheet4!U6 -> 6000 | C23: =Sheet4!V6 -> 1 | E23: =VLOOKUP(A23,[1]Sheet3!$A:$E,3,0) -> 0.854 | F23: =E23*C23*B23/1000 -> 5.124
A24: =Sheet4!T7 -> 9K-86009 | B24: =Sheet4!U7 -> 6000 | C24: =Sheet4!V7 -> 1 | E24: =VLOOKUP(A24,[1]Sheet3!$A:$E,3,0) -> 0.257 | F24: =E24*C24*B24/1000 -> 1.542
A25: =Sheet4!T8 -> K-85701 | B25: =Sheet4!U8 -> 5000 | C25: =Sheet4!V8 -> 1 | E25: =VLOOKUP(A25,[1]Sheet3!$A:$E,3,0) -> 0.921 | F25: =E25*C25*B25/1000 -> 4.605
A26: =Sheet4!T9 -> K-85702 | B26: =Sheet4!U9 -> 5000 | C26: =Sheet4!V9 -> 1 | E26: =VLOOKUP(A26,[1]Sheet3!$A:$E,3,0) -> 0.979 | F26: =E26*C26*B26/1000 -> 4.895
A27: =Sheet4!T10 -> K-85748 | B27: =Sheet4!U10 -> 5000 | C27: =Sheet4!V10 -> 1 | E27: =VLOOKUP(A27,[1]Sheet3!$A:$E,3,0) -> 0.979 | F27: =E27*C27*B27/1000 -> 4.895
A28: =Sheet4!T11 -> K-94389 | B28: =Sheet4!U11 -> 6000 | C28: =Sheet4!V11 -> 1 | E28: =VLOOKUP(A28,[1]Sheet3!$A:$E,3,0) -> 1.166 | F28: =E28*C28*B28/1000 -> 6.996
A29: =Sheet4!T12 -> K-94390 | B29: =Sheet4!U12 -> 6000 | C29: =Sheet4!V12 -> 1 | E29: =VLOOKUP(A29,[1]Sheet3!$A:$E,3,0) -> 1.358 | F29: =E29*C29*B29/1000 -> 8.148
A30: =Sheet4!T13 -> 9K-86072 | B30: =Sheet4!U13 -> 6000 | C30: =Sheet4!V13 -> 3 | E30: =VLOOKUP(A30,[1]Sheet3!$A:$E,3,0) -> 0.929 | F30: =E30*C30*B30/1000 -> 16.722
A31: =Sheet4!T14 -> 9K-86073 | B31: =Sheet4!U14 -> 6000 | C31: =Sheet4!V14 -> 1 | E31: =VLOOKUP(A31,[1]Sheet3!$A:$E,3,0) -> 0.404 | F31: =E31*C31*B31/1000 -> 2.424
A32: =Sheet4!T15 -> K-75696 | B32: =Sheet4!U15 -> 6000 | C32: =Sheet4!V15 -> 5 | E32: =VLOOKUP(A32,[1]Sheet3!$A:$E,3,0) -> 0.191 | F32: =E32*C32*B32/1000 -> 5.73
... A35: =Sheet4!T18 -> 9K-93034 | B35: =Sheet4!U18 -> 6000 | C35: =Sheet4!V18 -> 2 | E35: =VLOOKUP(A35,[1]Sheet3!$A:$E,3,0) -> 0.474 | F35: =E35*C35*B35/1000 -> 5.688
A36: KEBUTUHAN AKSESORIS DAN PART
A37: KODE | B37: Satuan | C37: QTY | D37: KETERANGAN | F37: =SUM(F21:F35) -> 102.103
A38: =Sheet5!K3 -> 2K-22464 | B38: =Sheet5!L3 -> mm | C38: =Sheet5!M3 -> 12460
A39: =Sheet5!K4 -> 9K-11072 | B39: =Sheet5!L4 -> Pcs | C39: =Sheet5!M4 -> 6
A40: =Sheet5!K5 -> 9K-11074 | B40: =Sheet5!L5 -> Pcs | C40: =Sheet5!M5 -> 96.844444
A41: =Sheet5!K6 -> 9K-30171 | B41: =Sheet5!L6 -> Pcs | C41: =Sheet5!M6 -> 96.844444
A42: =Sheet5!K7 -> CH 428 R/H BK DKS | B42: =Sheet5!L7 -> Pcs | C42: =Sheet5!M7 -> 2
A43: =Sheet5!K8 -> CYL DC DL60MM SN DKS | B43: =Sheet5!L8 -> Set | C43: =Sheet5!M8 -> 1
A44: =Sheet5!K9 -> DP 003 SSS DKS | B44: =Sheet5!L9 -> Set | C44: =Sheet5!M9 -> 1
A45: =Sheet5!K10 -> DS 886 SN DKS | B45: =Sheet5!L10 -> Set | C45: =Sheet5!M10 -> 1
A46: =Sheet5!K11 -> ESCN 855 SSS DKS | B46: =Sheet5!L11 -> Set | C46: =Sheet5!M11 -> 1
A47: =Sheet5!K12 -> ESS DL 4x3x3 2BB SSS DKS | B47: =Sheet5!L12 -> Set | C47: =Sheet5!M12 -> 3
...

Sheet P1-DSR
B5: =KOP!A14 -> P1-DSR_A2 STD | C5: =KOP!B14 -> YB1N
C6: =KOP!C14 -> 1 | D6: Unit
B8: HEIGTH | C8: 3195
B9: Rong Kusen Atas | C9: 755
B10: Rong Kusen Bawah | C10: =C8-C9-40*2 -> 2360
B11: Daun | C11: =C10-10 -> 2350
B12: Rong Daun | C12: =C11-200 -> 2150
B14: WIDTH | C14: 1590
B15: Rong Kusen | C15: =C14-40*2 -> 1510
B16: Daun | C16: =(C15-12)/2 -> 749
B17: Rong Daun | C17: =C16-82*2 -> 585
B20: Tinggi Anak Kunci :
B23: KODE | C23: PJG | D23: SAT | E23: QTY | F23: KETERANGAN | G23: BERAT | H23: TOTAL
A24: I. | B24: Profile | H24: =SUM(H25:H36) -> 21.885345
A25: V | B25: 9K-86001 | C25: =C8 -> 3195 | D25: mm | E25: =2*$C$6 -> 2 | F25: =VLOOKUP(B25,'[2]ALMINI YKK'!$B:$C,2,0) -> TIANG / AMBANG M 100MM (4 INCH) | G25: =VLOOKUP(B25,[3]Sheet3!$B:$E,3,0) -> 0.948 | H25: =G25*E25*C25/1000 -> 6.05772
A26: H | B26: 9K-86001 | C26: =C15-1 -> 1509 | D26: mm | E26: =1*$C$6 -> 1 | F26: =VLOOKUP(B26,'[2]ALMINI YKK'!$B:$C,2,0) -> TIANG / AMBANG M 100MM (4 INCH) | G26: =VLOOKUP(B26,[3]Sheet3!$B:$E,3,0) -> 0.948 | H26: =G26*E26*C26/1000 -> 1.430532
A27: H | B27: 9K-86007 | C27: =C26 -> 1509 | D27: mm | E27: =1*$C$6 -> 1 | F27: =VLOOKUP(B27,'[2]ALMINI YKK'!$B:$C,2,0) -> TUTUP KACA MATI 4 INCH (SF100) | G27: =VLOOKUP(B27,[3]Sheet3!$B:$E,3,0) -> 0.458 | H27: =G27*E27*C27/1000 -> 0.691122
A28: H | B28: 9K-86005 | C28: =C27 -> 1509 | D28: mm | E28: =1*$C$6 -> 1 | F28: =VLOOKUP(B28,'[2]ALMINI YKK'!$B:$C,2,0) -> AMBANG JIP 4 INCH(SF100) SCREW | G28: =VLOOKUP(B28,[3]Sheet3!$B:$E,3,0) -> 0.854 | H28: =G28*E28*C28/1000 -> 1.288686
A29: H | B29: 9K-86009 | C29: =C28 -> 1509 | D29: mm | E29: =1*$C$6 -> 1 | F29: =VLOOKUP(B29,'[2]ALMINI YKK'!$B:$C,2,0) -> CEKLOKAN JIP 4 INCH (SF100) | G29: =VLOOKUP(B29,[3]Sheet3!$B:$E,3,0) -> 0.257 | H29: =G29*E29*C29/1000 -> 0.387813
A30: V | B30: K-85701 | C30: =C11 -> 2350 | D30: mm | E30: =2*$C$6 -> 2 | F30: =VLOOKUP(B30,'[2]ALMINI YKK'!$B:$C,2,0) -> YF-TIANG ENGSEL 8CM SHD | G30: =VLOOKUP(B30,[3]Sheet3!$B:$E,3,0) -> 0.921 | H30: =G30*E30*C30/1000 -> 4.3287
A31: V | B31: K-85702 | C31: =C30 -> 2350 | D31: mm | E31: =1*$C$6 -> 1 | F31: =VLOOKUP(B31,'[2]ALMINI YKK'!$B:$C,2,0) -> YF-TIANG KAIT 8CMSHD POLOS | G31: =VLOOKUP(B31,[3]Sheet3!$B:$E,3,0) -> 0.979 | H31: =G31*E31*C31/1000 -> 2.30065
A32: V | B32: K-85748 | C32: =C30 -> 2350 | D32: mm | E32: =1*$C$6 -> 1 | F32: =VLOOKUP(B32,'[2]ALMINI YKK'!$B:$C,2,0) -> Tiang kait + Karet | G32: =VLOOKUP(B32,[3]Sheet3!$B:$E,3,0) -> 0.979 | H32: =G32*E32*C32/1000 -> 2.30065
A33: H | B33: K-94389 | C33: =C17+16+10 -> 611 | D33: mm | E33: =1*$C$6 -> 1 | F33: =VLOOKUP(B33,'[2]ALMINI YKK'!$B:$C,2,0) -> YF-AMBANG ATAS SHD | G33: =VLOOKUP(B33,[3]Sheet3!$B:$E,3,0) -> 1.166 | H33: =G33*E33*C33/1000 -> 0.712426
A34: H | B34: K-94390 | C34: =C33 -> 611 | D34: mm | E34: =1*$C$6 -> 1 | F34: =VLOOKUP(B34,'[2]ALMINI YKK'!$B:$C,2,0) -> YF-AMBANG BAWAH SHD | G34: =VLOOKUP(B34,[3]Sheet3!$B:$E,3,0) -> 1.358 | H34: =G34*E34*C34/1000 -> 0.829738
A35: H | B35: K-94389 | C35: =C17+16+16 -> 617 | D35: mm | E35: =1*$C$6 -> 1 | F35: =VLOOKUP(B35,'[2]ALMINI YKK'!$B:$C,2,0) -> YF-AMBANG ATAS SHD | G35: =VLOOKUP(B35,[3]Sheet3!$B:$E,3,0) -> 1.166 | H35: =G35*E35*C35/1000 -> 0.719422
A36: H | B36: K-94390 | C36: =C35 -> 617 | D36: mm | E36: =1*$C$6 -> 1 | F36: =VLOOKUP(B36,'[2]ALMINI YKK'!$B:$C,2,0) -> YF-AMBANG BAWAH SHD | G36: =VLOOKUP(B36,[3]Sheet3!$B:$E,3,0) -> 1.358 | H36: =G36*E36*C36/1000 -> 0.837886
A38: II. | B38: =[4]BOM!B24 -> Hardwares
B39: ESS DL 4x3x3 2BB SSS DKS | D39: Set | E39: =1.5*$C$6*2 -> 3
B40: MTS RL DL 8485 SSS DKS | D40: Set | E40: =1*$C$6 -> 1
B41: PH DL446 32x600x400 SSS DKS | D41: Set | E41: =2*$C$6 -> 2
B42: CYL DC DL60MM SN DKS | D42: Set | E42: =1*$C$6 -> 1
B43: ESCN 855 SSS DKS | D43: Set | E43: =1*$C$6 -> 1
B44: DS 886 SN DKS | D44: Set | E44: =1*$C$6 -> 1
B45: FB 508 NA DKS | D45: Set | E45: =1*$C$6 -> 1
B46: DP 003 SSS DKS | D46: Set | E46: =1*$C$6 -> 1
A48: III. | B48: Parts
B49: SEALER PAD | D49: Pcs | E49: =4*$C$6 -> 4 | F49: SEALER PAD STANDART
B50: SCREW 8X3/4 P | D50: Pcs | E50: =(E49)*2 -> 8 | F50: SCREW KUSEN
B51: SCREW 8X3 | D51: Pcs | E51: =(2+(($C$8-240)/450+2+($C$14-240)/450))*2*$C$6 -> 27.133333 | F51: SCREW TEMBOK
B52: FISHER S6 | D52: Pcs | E52: =E51 -> 27.133333 | F52: FISHER S6 SCREW TEMBOK
...

Sheet J1-DSR
B4: =KOP!A15 -> J1-DSR_A2 STD | C4: =KOP!B15 -> YB1N
C5: =KOP!C15 -> 1 | D5: Unit
B7: HEIGTH | C7: 2890
B8: Rong Kusen Atas | C8: 755
B9: Rong Kusen Bawah | C9: =C7-C8-40*3 -> 2015
B11: WIDTH | C11: 1160
B12: Rong Kusen | C12: =C11-40*2 -> 1080
A22: No. | B22: KODE | C22: PJG | D22: SAT | E22: QTY | F22: KETERANGAN | G22: BERAT | H22: TOTAL
A23: I. | B23: Profile | H23: =SUM(H24:H29) -> 10.667701
A24: V | B24: 9K-86072 | C24: =C7 -> 2890 | D24: mm | E24: =2*$C$5 -> 2 | F24: =VLOOKUP(B24,'[5]ALMINI YKK'!$B:$C,2,0) -> TIANG/AMBANG JENDELA 4 INCH (SF100) | G24: =VLOOKUP(B24,[3]Sheet3!$B:$E,3,0) -> 0.929 | H24: =G24*E24*C24/1000 -> 5.36962
A25: H | B25: 9K-86072 | C25: =C26 -> 1079 | D25: mm | E25: =3*$C$5 -> 3 | F25: =VLOOKUP(B25,'[5]ALMINI YKK'!$B:$C,2,0) -> TIANG/AMBANG JENDELA 4 INCH (SF100) | G25: =VLOOKUP(B25,[3]Sheet3!$B:$E,3,0) -> 0.929 | H25: =G25*E25*C25/1000 -> 3.007173
A26: H | B26: 9K-86073 | C26: =C12-1 -> 1079 | D26: mm | E26: =1*$C$5 -> 1 | F26: =VLOOKUP(B26,'[5]ALMINI YKK'!$B:$C,2,0) -> TUTUP + TATAPAN JENDELA 4 INCH (SF100) | G26: =VLOOKUP(B26,[3]Sheet3!$B:$E,3,0) -> 0.404 | H26: =G26*E26*C26/1000 -> 0.435916
A27: V | B27: K-75696 | C27: =C9-36 -> 1979 | D27: mm | E27: =2*$C$5 -> 2 | F27: =VLOOKUP(B27,'[5]ALMINI YKK'!$B:$C,2,0) -> BEAD CASEMENT | G27: =VLOOKUP(B27,[3]Sheet3!$B:$E,3,0) -> 0.191 | H27: =G27*E27*C27/1000 -> 0.755978
A28: V | B28: K-75696 | C28: =C8-36 -> 719 | D28: mm | E28: =2*$C$5 -> 2 | F28: =VLOOKUP(B28,'[5]ALMINI YKK'!$B:$C,2,0) -> BEAD CASEMENT | G28: =VLOOKUP(B28,[3]Sheet3!$B:$E,3,0) -> 0.191 | H28: =G28*E28*C28/1000 -> 0.274658
A29: H | B29: K-75696 | C29: =C26 -> 1079 | D29: mm | E29: =4*$C$5 -> 4 | F29: =VLOOKUP(B29,'[5]ALMINI YKK'!$B:$C,2,0) -> BEAD CASEMENT | G29: =VLOOKUP(B29,[3]Sheet3!$B:$E,3,0) -> 0.191 | H29: =G29*E29*C29/1000 -> 0.824356
A31: II. | B31: Hardwares
A33: III. | B33: Parts
B34: SEALER PAD | D34: Pcs | E34: =4*$C$5 -> 4 | F34: SEALER PAD STANDART
B35: SEALER PAD | D35: Pcs | E35: =2*$C$5 -> 2 | F35: SEALER PAD TENGAH
B36: 9K-30171 | D36: Pcs | E36: =((2+(($C$7-240)/450+2+($C$11-240)/450))*2)*$C$5 -> 23.866667 | F36: =VLOOKUP(B36,'[5]ASESORIS+GASKET'!$B:$C,2,0) -> TUTUP SCRUP
B37: SCREW 8X3 JF | D37: Pcs | E37: =((2+(($C$7-240)/450+2+($C$11-240)/450))*2)*$C$5 -> 23.866667 | F37: =VLOOKUP(B37,'[5]ASESORIS+GASKET'!$B:$C,2,0) -> SCREW TEMBOK
B38: SCREW 8 X 3/4 JP | D38: Pcs | E38: =(E34+E35)*$C$5 -> 6 | F38: =VLOOKUP(B38,'[5]ASESORIS+GASKET'!$B:$C,2,0) -> SCREW KUSEN
B39: FISHER S6 | D39: Pcs | E39: =((2+(($C$7-240)/450+2+($C$11-240)/450))*2)*$C$5 -> 23.866667 | F39: =VLOOKUP(B39,'[5]ASESORIS+GASKET'!$B:$C,2,0) -> FISHER S6 SCREW TEMBOK
B40: SCREW 6 X 1/2 JP | D40: Pcs | E40: 0 | F40: =VLOOKUP(B40,'[5]ASESORIS+GASKET'!$B:$C,2,0) -> SCREW CASEMENT
B41: 9K-11074 | D41: Pcs | E41: =E39 -> 23.866667 | F41: Shim Receiver ( Atas & samping )
B42: 9K-11072 | D42: Pcs | E42: =1*$C$5 -> 1 | F42: Shim Receiver ( bawah )
B43: 9K-20602 | D43: Pcs | E43: 0 | F43: Setting Block ( ganjel kaca harus terpasang di workshop )
B44: 2K-30630 | D44: Set | E44: 0 | F44: Pulling Block
B45: Foam Kusen - Dinding | C45: =C11*2*2*C5+C7*2*2*C5 -> 16200 | D45: mm | E45: - | F45: Backer Road 8mm
A47: IV. | B47: Gasket
A49: V. | B49: Sealant
B50: Sealant Kusen - Dinding | C50: =C45 -> 16200 | D50: mm | E50: - | F50: =$C$50/1000*0.006*0.007*1000*1000 -> 680.4 | G50: ml | H50: =F50+F51 -> 1677.06
B51: Sealant Kusen - Kaca | C51: =C11*2*4*C5+C7*2*2*C5+C7 -> 23730 | D51: mm | E51: - | F51: =$C$51/1000*0.006*0.007*1000*1000 -> 996.66 | G51: ml
A53: VI. | B53: Glass
B54: =CONCATENATE($B$4,"_",J54) -> J1-DSR_A2 STD_FIX.A | E54: =2*$C$5 -> 2 | F54: =CONCATENATE((C12-36-8+14)/2," x ",C8-36+14) -> 525 x 733 | G54: FLT 6 | J54: FIX.A
B55: =CONCATENATE($B$4,"_",J55) -> J1-DSR_A2 STD_FIX.B | E55: =2*$C$5 -> 2 | F55: =CONCATENATE((C12-36-8+14)/2," x ",C9-36+14) -> 525 x 1993 | G55: FLT 6 | J55: FIX.B

Sheet J2-DSR
B4: =KOP!A16 -> J2-DSR_A2 STD | C4: =KOP!B16 -> YB1N
C5: =KOP!C16 -> 1 | D5: Unit
B7: HEIGTH | C7: 2890
B8: Rong Kusen Atas | C8: 755
B9: Rong Kusen Bawah | C9: =C7-C8-40*3 -> 2015
B11: WIDTH | C11: 560
B12: Rong Kusen | C12: =C11-40*2 -> 480
A22: No. | B22: KODE | C22: PJG | D22: SAT | E22: QTY | F22: KETERANGAN | G22: BERAT | H22: TOTAL
A23: I. | B23: Profile | H23: =SUM(H24:H29) -> 8.294701
A24: V | B24: 9K-86072 | C24: =C7 -> 2890 | D24: mm | E24: =2*$C$5 -> 2 | F24: =VLOOKUP(B24,'[5]ALMINI YKK'!$B:$C,2,0) -> TIANG/AMBANG JENDELA 4 INCH (SF100) | G24: =VLOOKUP(B24,[3]Sheet3!$B:$E,3,0) -> 0.929 | H24: =G24*E24*C24/1000 -> 5.36962
A25: H | B25: 9K-86072 | C25: =C26 -> 479 | D25: mm | E25: =3*$C$5 -> 3 | F25: =VLOOKUP(B25,'[5]ALMINI YKK'!$B:$C,2,0) -> TIANG/AMBANG JENDELA 4 INCH (SF100) | G25: =VLOOKUP(B25,[3]Sheet3!$B:$E,3,0) -> 0.929 | H25: =G25*E25*C25/1000 -> 1.334973
A26: H | B26: 9K-86073 | C26: =C12-1 -> 479 | D26: mm | E26: =1*$C$5 -> 1 | F26: =VLOOKUP(B26,'[5]ALMINI YKK'!$B:$C,2,0) -> TUTUP + TATAPAN JENDELA 4 INCH (SF100) | G26: =VLOOKUP(B26,[3]Sheet3!$B:$E,3,0) -> 0.404 | H26: =G26*E26*C26/1000 -> 0.193516
A27: V | B27: K-75696 | C27: =C9-36 -> 1979 | D27: mm | E27: =2*$C$5 -> 2 | F27: =VLOOKUP(B27,'[5]ALMINI YKK'!$B:$C,2,0) -> BEAD CASEMENT | G27: =VLOOKUP(B27,[3]Sheet3!$B:$E,3,0) -> 0.191 | H27: =G27*E27*C27/1000 -> 0.755978
A28: V | B28: K-75696 | C28: =C8-36 -> 719 | D28: mm | E28: =2*$C$5 -> 2 | F28: =VLOOKUP(B28,'[5]ALMINI YKK'!$B:$C,2,0) -> BEAD CASEMENT | G28: =VLOOKUP(B28,[3]Sheet3!$B:$E,3,0) -> 0.191 | H28: =G28*E28*C28/1000 -> 0.274658
A29: H | B29: K-75696 | C29: =C26 -> 479 | D29: mm | E29: =4*$C$5 -> 4 | F29: =VLOOKUP(B29,'[5]ALMINI YKK'!$B:$C,2,0) -> BEAD CASEMENT | G29: =VLOOKUP(B29,[3]Sheet3!$B:$E,3,0) -> 0.191 | H29: =G29*E29*C29/1000 -> 0.365956
A31: II. | B31: Hardwares
A33: III. | B33: Parts
B34: SEALER PAD | D34: Pcs | E34: =4*$C$5 -> 4 | F34: SEALER PAD STANDART
B35: SEALER PAD | D35: Pcs | E35: =2*$C$5 -> 2 | F35: SEALER PAD TENGAH
B36: 9K-30171 | D36: Pcs | E36: =((2+(($C$7-240)/450+2+($C$11-240)/450))*2)*$C$5 -> 21.2 | F36: =VLOOKUP(B36,'[5]ASESORIS+GASKET'!$B:$C,2,0) -> TUTUP SCRUP
B37: SCREW 8X3 JF | D37: Pcs | E37: =((2+(($C$7-240)/450+2+($C$11-240)/450))*2)*$C$5 -> 21.2 | F37: =VLOOKUP(B37,'[5]ASESORIS+GASKET'!$B:$C,2,0) -> SCREW TEMBOK
B38: SCREW 8 X 3/4 JP | D38: Pcs | E38: =(E34+E35)*$C$5 -> 6 | F38: =VLOOKUP(B38,'[5]ASESORIS+GASKET'!$B:$C,2,0) -> SCREW KUSEN
B39: FISHER S6 | D39: Pcs | E39: =((2+(($C$7-240)/450+2+($C$11-240)/450))*2)*$C$5 -> 21.2 | F39: =VLOOKUP(B39,'[5]ASESORIS+GASKET'!$B:$C,2,0) -> FISHER S6 SCREW TEMBOK
B40: SCREW 6 X 1/2 JP | D40: Pcs | E40: 0 | F40: =VLOOKUP(B40,'[5]ASESORIS+GASKET'!$B:$C,2,0) -> SCREW CASEMENT
B41: 9K-11074 | D41: Pcs | E41: =E39 -> 21.2 | F41: Shim Receiver ( Atas & samping )
B42: 9K-11072 | D42: Pcs | E42: =1*$C$5 -> 1 | F42: Shim Receiver ( bawah )
B43: 9K-20602 | D43: Pcs | E43: 0 | F43: Setting Block ( ganjel kaca harus terpasang di workshop )
B44: 2K-30630 | D44: Set | E44: 0 | F44: Pulling Block
B45: Foam Kusen - Dinding | C45: =C11*2*2*C5+C7*2*2*C5 -> 13800 | D45: mm | E45: - | F45: Backer Road 8mm
A47: IV. | B47: Gasket
A49: V. | B49: Sealant
B50: Sealant Kusen - Dinding | C50: =C45 -> 13800 | D50: mm | E50: - | F50: =$C$50/1000*0.006*0.007*1000*1000 -> 579.6 | G50: ml | H50: =F50+F51 -> 1374.66
B51: Sealant Kusen - Kaca | C51: =C11*2*4*C5+C7*2*2*C5+C7 -> 18930 | D51: mm | E51: - | F51: =$C$51/1000*0.006*0.007*1000*1000 -> 795.06 | G51: ml
A53: VI. | B53: Glass
B54: =CONCATENATE($B$4,"_",J54) -> J2-DSR_A2 STD_FIX.A | E54: =1*$C$5 -> 1 | F54: =CONCATENATE(C12-36+14," x ",C8-36+14) -> 458 x 733 | G54: FLT 6 | J54: FIX.A
B55: =CONCATENATE($B$4,"_",J55) -> J2-DSR_A2 STD_FIX.B | E55: =1*$C$5 -> 1 | F55: =CONCATENATE(C12-36+14," x ",C9-36+14) -> 458 x 1993 | G55: FLT 6 | J55: FIX.B

Sheet J2-01
B4: =KOP!A17 -> J2-01_A2 STD | C4: =KOP!B14 -> YB1N
C5: =KOP!C17 -> 2 | D5: Unit
B7: HEIGTH | C7: 2090
B8: Rong Kusen Atas | C8: 360
B9: Rong Kusen Bawah | C9: =C7-C8-35*3 -> 1625
B10: Daun | C10: =C9-10 -> 1615
B11: Rong Daun | C11: =C10-44*2 -> 1527
B13: WIDTH | C13: 2415
B14: Rong Kusen Fix | C14: 1510
B15: Rong Kusen TH | C15: =C13-C14-35*3 -> 800
B16: Daun | C16: =C15-10 -> 790
B17: Rong Daun | C17: =C16-44*2 -> 702
A19: No. | B19: KODE | C19: PJG | D19: SAT | E19: QTY | F19: KETERANGAN | G19: BERAT | H19: TOTAL
A20: I. | B20: Profile | H20: =SUM(H21:H30) -> 24.480468
A21: V | B21: 9K-86061 | C21: =C7 -> 2090 | D21: mm | E21: =3*$C$5 -> 6 | F21: =VLOOKUP(B21,'[5]ALMINI YKK'!$B:$C,2,0) -> Open Back Tanduk 3 Inch with Screw | G21: =VLOOKUP(B21,[3]Sheet3!$B:$E,3,0) -> 0.601 | H21: =G21*E21*C21/1000 -> 7.53654
A22: V | B22: 9K-86063 | C22: =C21 -> 2090 | D22: mm | E22: =1*$C$5 -> 2 | F22: =VLOOKUP(B22,'[5]ALMINI YKK'!$B:$C,2,0) -> Tutup Tanduk 3 inch | G22: =VLOOKUP(B22,[3]Sheet3!$B:$E,3,0) -> 0.265 | H22: =G22*E22*C22/1000 -> 1.1077
A23: H | B23: 9K-86061 | C23: =C14-1 -> 1509 | D23: mm | E23: =3*$C$5 -> 6 | F23: =VLOOKUP(B23,'[5]ALMINI YKK'!$B:$C,2,0) -> Open Back Tanduk 3 Inch with Screw | G23: =VLOOKUP(B23,[3]Sheet3!$B:$E,3,0) -> 0.601 | H23: =G23*E23*C23/1000 -> 5.441454
A24: H | B24: 9K-86063 | C24: =C23 -> 1509 | D24: mm | E24: =1*$C$5 -> 2 | F24: =VLOOKUP(B24,'[5]ALMINI YKK'!$B:$C,2,0) -> Tutup Tanduk 3 inch | G24: =VLOOKUP(B24,[3]Sheet3!$B:$E,3,0) -> 0.265 | H24: =G24*E24*C24/1000 -> 0.79977
A25: H | B25: 9K-86061 | C25: =C15-1 -> 799 | D25: mm | E25: =3*$C$5 -> 6 | F25: =VLOOKUP(B25,'[5]ALMINI YKK'!$B:$C,2,0) -> Open Back Tanduk 3 Inch with Screw | G25: =VLOOKUP(B25,[3]Sheet3!$B:$E,3,0) -> 0.601 | H25: =G25*E25*C25/1000 -> 2.881194
A26: H | B26: 9K-86063 | C26: =C25 -> 799 | D26: mm | E26: =1*$C$5 -> 2 | F26: =VLOOKUP(B26,'[5]ALMINI YKK'!$B:$C,2,0) -> Tutup Tanduk 3 inch | G26: =VLOOKUP(B26,[3]Sheet3!$B:$E,3,0) -> 0.265 | H26: =G26*E26*C26/1000 -> 0.42347
A27: V | B27: 9K-93034 | C27: =C10 -> 1615 | D27: mm | E27: =2*$C$5 -> 4 | F27: =VLOOKUP(B27,'[5]ALMINI YKK'!$B:$C,2,0) -> FRAME CASEMENT JENDELA ALUMCO 44 mm | G27: =VLOOKUP(B27,[3]Sheet3!$B:$E,3,0) -> 0.474 | H27: =G27*E27*C27/1000 -> 3.06204
A28: V | B28: K-75696 | C28: =C11 -> 1527 | D28: mm | E28: =2*$C$5 -> 4 | F28: =VLOOKUP(B28,'[5]ALMINI YKK'!$B:$C,2,0) -> BEAD CASEMENT | G28: =VLOOKUP(B28,[3]Sheet3!$B:$E,3,0) -> 0.191 | H28: =G28*E28*C28/1000 -> 1.166628
A29: H | B29: 9K-93034 | C29: =C16 -> 790 | D29: mm | E29: =2*$C$5 -> 4 | F29: =VLOOKUP(B29,'[5]ALMINI YKK'!$B:$C,2,0) -> FRAME CASEMENT JENDELA ALUMCO 44 mm | G29: =VLOOKUP(B29,[3]Sheet3!$B:$E,3,0) -> 0.474 | H29: =G29*E29*C29/1000 -> 1.49784
A30: H | B30: K-75696 | C30: =C17+18*2 -> 738 | D30: mm | E30: =2*$C$5 -> 4 | F30: =VLOOKUP(B30,'[5]ALMINI YKK'!$B:$C,2,0) -> BEAD CASEMENT | G30: =VLOOKUP(B30,[3]Sheet3!$B:$E,3,0) -> 0.191 | H30: =G30*E30*C30/1000 -> 0.563832
A32: II. | B32: Hardwares
B33: CH 428 R/H BK DKS | D33: Pcs | E33: =1*$C$5 -> 2 | F33: =CONCATENATE("Rambuncis"," ",B33) -> Rambuncis CH 428 R/H BK DKS
B34: FS S/S 24" DKS | D34: Psg | E34: =1*$C$5 -> 2 | F34: =CONCATENATE("","Friction Stay ",B34) -> Friction Stay FS S/S 24" DKS
A36: III. | B36: Parts
B37: SEALER PAD | D37: Pcs | E37: =8*$C$5 -> 16 | F37: SEALER PAD STANDART
B38: SEALER PAD | D38: Pcs | E38: =4*$C$5 -> 8 | F38: SEALER PAD TENGAH
B39: 9K-30171 | D39: Pcs | E39: =((2+(($C$7-240)/450+2+($C$13-240)/450))*2)*$C$5 -> 51.777778 | F39: =VLOOKUP(B39,'[5]ASESORIS+GASKET'!$B:$C,2,0) -> TUTUP SCRUP
B40: SCREW 8X3 JF | D40: Pcs | E40: =((2+(($C$7-240)/450+2+($C$13-240)/450))*2)*$C$5 -> 51.777778 | F40: =VLOOKUP(B40,'[5]ASESORIS+GASKET'!$B:$C,2,0) -> SCREW TEMBOK
B41: FISHER S6 | D41: Pcs | E41: =((2+(($C$7-240)/450+2+($C$13-240)/450))*2)*$C$5 -> 51.777778 | F41: =VLOOKUP(B41,'[5]ASESORIS+GASKET'!$B:$C,2,0) -> FISHER S6 SCREW TEMBOK
B42: SCREW 6 X 1/2 JP | D42: Pcs | E42: =8*E34 -> 16 | F42: =VLOOKUP(B42,'[5]ASESORIS+GASKET'!$B:$C,2,0) -> SCREW CASEMENT
B43: SCREW 8 X 3/4 JP | D43: Pcs | E43: =2*E37+2*E38 -> 48 | F43: =VLOOKUP(B43,'[5]ASESORIS+GASKET'!$B:$C,2,0) -> SCREW KUSEN
B44: 9K-11074 | D44: Pcs | E44: =E41 -> 51.777778 | F44: Shim Receiver ( samping )
B45: 9K-11072 | D45: Pcs | E45: =2*$C$5 -> 4 | F45: Shim Receiver ( bawah )
B46: Foam Kusen - Dinding | C46: =C13*2*2*C5+C7*2*2*C5 -> 36040 | D46: mm | E46: - | F46: Backer Road 8mm
A48: IV. | B48: Gasket
B49: Gasket Sirip SF Black | C49: =C16*2*1*C5+C10*2*1*C5 -> 9620 | D49: mm | E49: -
...

Sheet Sheet4
B4: ='P1-DSR'!C25 -> 3195 | C4: ='P1-DSR'!D25 -> mm | D4: ='P1-DSR'!E25 -> 2 | E4: ='P1-DSR'!B25 -> 9K-86001 | K4: 6000 | M4: 1000 | N4: 9K-86001 | T4: 9K-86001 | U4: 6000 | V4: 2
B5: ='P1-DSR'!C26 -> 1509 | C5: ='P1-DSR'!D26 -> mm | D5: ='P1-DSR'!E26 -> 1 | E5: ='P1-DSR'!B26 -> 9K-86001 | K5: 6000 | M5: 1000 | N5: 9K-86007 | T5: 9K-86007 | U5: 6000 | V5: 1
B6: ='P1-DSR'!C27 -> 1509 | C6: ='P1-DSR'!D27 -> mm | D6: ='P1-DSR'!E27 -> 1 | E6: ='P1-DSR'!B27 -> 9K-86007 | K6: 6000 | M6: 1000 | N6: 9K-86005 | T6: 9K-86005 | U6: 6000 | V6: 1
B7: ='P1-DSR'!C28 -> 1509 | C7: ='P1-DSR'!D28 -> mm | D7: ='P1-DSR'!E28 -> 1 | E7: ='P1-DSR'!B28 -> 9K-86005 | K7: 6000 | M7: 1000 | N7: 9K-86009 | T7: 9K-86009 | U7: 6000 | V7: 1
B8: ='P1-DSR'!C29 -> 1509 | C8: ='P1-DSR'!D29 -> mm | D8: ='P1-DSR'!E29 -> 1 | E8: ='P1-DSR'!B29 -> 9K-86009 | K8: 5000 | M8: 1000 | N8: K-85701 | T8: K-85701 | U8: 5000 | V8: 1
B9: ='P1-DSR'!C30 -> 2350 | C9: ='P1-DSR'!D30 -> mm | D9: ='P1-DSR'!E30 -> 2 | E9: ='P1-DSR'!B30 -> K-85701 | K9: 5000 | M9: 1000 | N9: K-85702 | T9: K-85702 | U9: 5000 | V9: 1
B10: ='P1-DSR'!C31 -> 2350 | C10: ='P1-DSR'!D31 -> mm | D10: ='P1-DSR'!E31 -> 1 | E10: ='P1-DSR'!B31 -> K-85702 | K10: 5000 | M10: 1000 | N10: K-85748 | T10: K-85748 | U10: 5000 | V10: 1
B11: ='P1-DSR'!C32 -> 2350 | C11: ='P1-DSR'!D32 -> mm | D11: ='P1-DSR'!E32 -> 1 | E11: ='P1-DSR'!B32 -> K-85748 | K11: 6000 | M11: 1000 | N11: K-94389 | T11: K-94389 | U11: 6000 | V11: 1
B12: ='P1-DSR'!C33 -> 611 | C12: ='P1-DSR'!D33 -> mm | D12: ='P1-DSR'!E33 -> 1 | E12: ='P1-DSR'!B33 -> K-94389 | K12: 6000 | M12: 1000 | N12: K-94390 | T12: K-94390 | U12: 6000 | V12: 1
B13: ='P1-DSR'!C34 -> 611 | C13: ='P1-DSR'!D34 -> mm | D13: ='P1-DSR'!E34 -> 1 | E13: ='P1-DSR'!B34 -> K-94390 | K13: 6000 | M13: 1000 | N13: 9K-86072 | T13: 9K-86072 | U13: 6000 | V13: 3
B14: ='P1-DSR'!C35 -> 617 | C14: ='P1-DSR'!D35 -> mm | D14: ='P1-DSR'!E35 -> 1 | E14: ='P1-DSR'!B35 -> K-94389 | K14: 6000 | M14: 1000 | N14: 9K-86073 | T14: 9K-86073 | U14: 6000 | V14: 1
B15: ='P1-DSR'!C36 -> 617 | C15: ='P1-DSR'!D36 -> mm | D15: ='P1-DSR'!E36 -> 1 | E15: ='P1-DSR'!B36 -> K-94390 | K15: 6000 | M15: 1000 | N15: K-75696 | T15: K-75696 | U15: 6000 | V15: 5
B16: ='J1-DSR'!C24 -> 2890 | C16: ='J1-DSR'!D24 -> mm | D16: ='J1-DSR'!E24 -> 2 | E16: ='J1-DSR'!B24 -> 9K-86072 | K16: 6000 | M16: 1000 | N16: 9K-86061 | T16: 9K-86061 | U16: 6000 | V16: 5
B17: ='J1-DSR'!C25 -> 1079 | C17: ='J1-DSR'!D25 -> mm | D17: ='J1-DSR'!E25 -> 3 | E17: ='J1-DSR'!B25 -> 9K-86072 | K17: 6000 | M17: 1000 | N17: 9K-86063 | T17: 9K-86063 | U17: 6000 | V17: 2
B18: ='J1-DSR'!C26 -> 1079 | C18: ='J1-DSR'!D26 -> mm | D18: ='J1-DSR'!E26 -> 1 | E18: ='J1-DSR'!B26 -> 9K-86073 | K18: 6000 | M18: 1000 | N18: 9K-93034 | T18: 9K-93034 | U18: 6000 | V18: 2
B19: ='J1-DSR'!C27 -> 1979 | C19: ='J1-DSR'!D27 -> mm | D19: ='J1-DSR'!E27 -> 2 | E19: ='J1-DSR'!B27 -> K-75696
B20: ='J1-DSR'!C28 -> 719 | C20: ='J1-DSR'!D28 -> mm | D20: ='J1-DSR'!E28 -> 2 | E20: ='J1-DSR'!B28 -> K-75696
B21: ='J1-DSR'!C29 -> 1079 | C21: ='J1-DSR'!D29 -> mm | D21: ='J1-DSR'!E29 -> 4 | E21: ='J1-DSR'!B29 -> K-75696
B22: ='J2-DSR'!C24 -> 2890 | C22: ='J2-DSR'!D24 -> mm | D22: ='J2-DSR'!E24 -> 2 | E22: ='J2-DSR'!B24 -> 9K-86072
B23: ='J2-DSR'!C25 -> 479 | C23: ='J2-DSR'!D25 -> mm | D23: ='J2-DSR'!E25 -> 3 | E23: ='J2-DSR'!B25 -> 9K-86072
B24: ='J2-DSR'!C26 -> 479 | C24: ='J2-DSR'!D26 -> mm | D24: ='J2-DSR'!E26 -> 1 | E24: ='J2-DSR'!B26 -> 9K-86073
B25: ='J2-DSR'!C27 -> 1979 | C25: ='J2-DSR'!D27 -> mm | D25: ='J2-DSR'!E27 -> 2 | E25: ='J2-DSR'!B27 -> K-75696
B26: ='J2-DSR'!C28 -> 719 | C26: ='J2-DSR'!D28 -> mm | D26: ='J2-DSR'!E28 -> 2 | E26: ='J2-DSR'!B28 -> K-75696
B27: ='J2-DSR'!C29 -> 479 | C27: ='J2-DSR'!D29 -> mm | D27: ='J2-DSR'!E29 -> 4 | E27: ='J2-DSR'!B29 -> K-75696
B28: ='J2-01'!C21 -> 2090 | C28: ='J2-01'!D21 -> mm | D28: ='J2-01'!E21 -> 6 | E28: ='J2-01'!B21 -> 9K-86061
B29: ='J2-01'!C22 -> 2090 | C29: ='J2-01'!D22 -> mm | D29: ='J2-01'!E22 -> 2 | E29: ='J2-01'!B22 -> 9K-86063
B30: ='J2-01'!C23 -> 1509 | C30: ='J2-01'!D23 -> mm | D30: ='J2-01'!E23 -> 6 | E30: ='J2-01'!B23 -> 9K-86061
B31: ='J2-01'!C24 -> 1509 | C31: ='J2-01'!D24 -> mm | D31: ='J2-01'!E24 -> 2 | E31: ='J2-01'!B24 -> 9K-86063
B32: ='J2-01'!C25 -> 799 | C32: ='J2-01'!D25 -> mm | D32: ='J2-01'!E25 -> 6 | E32: ='J2-01'!B25 -> 9K-86061
B33: ='J2-01'!C26 -> 799 | C33: ='J2-01'!D26 -> mm | D33: ='J2-01'!E26 -> 2 | E33: ='J2-01'!B26 -> 9K-86063
B34: ='J2-01'!C27 -> 1615 | C34: ='J2-01'!D27 -> mm | D34: ='J2-01'!E27 -> 4 | E34: ='J2-01'!B27 -> 9K-93034
B35: ='J2-01'!C28 -> 1527 | C35: ='J2-01'!D28 -> mm | D35: ='J2-01'!E28 -> 4 | E35: ='J2-01'!B28 -> K-75696
B36: ='J2-01'!C29 -> 790 | C36: ='J2-01'!D29 -> mm | D36: ='J2-01'!E29 -> 4 | E36: ='J2-01'!B29 -> 9K-93034
B37: ='J2-01'!C30 -> 738 | C37: ='J2-01'!D30 -> mm | D37: ='J2-01'!E30 -> 4 | E37: ='J2-01'!B30 -> K-75696

Sheet Sheet5
B3: ='P1-DSR'!B39 -> ESS DL 4x3x3 2BB SSS DKS | C3: ='P1-DSR'!C39 -> 0 | D3: ='P1-DSR'!D39 -> Set | E3: ='P1-DSR'!E39 -> 3 | K3: 2K-22464 | L3: mm | M3: =SUMIF(B:B,K:K,C:C) -> 12460
B4: ='P1-DSR'!B40 -> MTS RL DL 8485 SSS DKS | C4: ='P1-DSR'!C40 -> 0 | D4: ='P1-DSR'!D40 -> Set | E4: ='P1-DSR'!E40 -> 1 | K4: 9K-11072 | L4: Pcs | M4: =SUMIF(B:B,K:K,E:E) -> 6
B5: ='P1-DSR'!B41 -> PH DL446 32x600x400 SSS DKS | C5: ='P1-DSR'!C41 -> 0 | D5: ='P1-DSR'!D41 -> Set | E5: ='P1-DSR'!E41 -> 2 | K5: 9K-11074 | L5: Pcs | M5: =SUMIF(B:B,K:K,E:E) -> 96.844444
B6: ='P1-DSR'!B42 -> CYL DC DL60MM SN DKS | C6: ='P1-DSR'!C42 -> 0 | D6: ='P1-DSR'!D42 -> Set | E6: ='P1-DSR'!E42 -> 1 | K6: 9K-30171 | L6: Pcs | M6: =SUMIF(B:B,K:K,E:E) -> 96.844444
B7: ='P1-DSR'!B43 -> ESCN 855 SSS DKS | C7: ='P1-DSR'!C43 -> 0 | D7: ='P1-DSR'!D43 -> Set | E7: ='P1-DSR'!E43 -> 1 | K7: CH 428 R/H BK DKS | L7: Pcs | M7: =SUMIF(B:B,K:K,E:E) -> 2
B8: ='P1-DSR'!B44 -> DS 886 SN DKS | C8: ='P1-DSR'!C44 -> 0 | D8: ='P1-DSR'!D44 -> Set | E8: ='P1-DSR'!E44 -> 1 | K8: CYL DC DL60MM SN DKS | L8: Set | M8: =SUMIF(B:B,K:K,E:E) -> 1
B9: ='P1-DSR'!B45 -> FB 508 NA DKS | C9: ='P1-DSR'!C45 -> 0 | D9: ='P1-DSR'!D45 -> Set | E9: ='P1-DSR'!E45 -> 1 | K9: DP 003 SSS DKS | L9: Set | M9: =SUMIF(B:B,K:K,E:E) -> 1
B10: ='P1-DSR'!B46 -> DP 003 SSS DKS | C10: ='P1-DSR'!C46 -> 0 | D10: ='P1-DSR'!D46 -> Set | E10: ='P1-DSR'!E46 -> 1 | K10: DS 886 SN DKS | L10: Set | M10: =SUMIF(B:B,K:K,E:E) -> 1
B11: ='P1-DSR'!B47 -> 0 | C11: ='P1-DSR'!C47 -> 0 | D11: ='P1-DSR'!D47 -> 0 | E11: ='P1-DSR'!E47 -> 0 | K11: ESCN 855 SSS DKS | L11: Set | M11: =SUMIF(B:B,K:K,E:E) -> 1
B12: ='P1-DSR'!B48 -> Parts | C12: ='P1-DSR'!C48 -> 0 | D12: ='P1-DSR'!D48 -> 0 | E12: ='P1-DSR'!E48 -> 0 | K12: ESS DL 4x3x3 2BB SSS DKS | L12: Set | M12: =SUMIF(B:B,K:K,E:E) -> 3
B13: ='P1-DSR'!B49 -> SEALER PAD | C13: ='P1-DSR'!C49 -> 0 | D13: ='P1-DSR'!D49 -> Pcs | E13: ='P1-DSR'!E49 -> 4 | K13: FB 508 NA DKS | L13: Set | M13: =SUMIF(B:B,K:K,E:E) -> 1
B14: ='P1-DSR'!B50 -> SCREW 8X3/4 P | C14: ='P1-DSR'!C50 -> 0 | D14: ='P1-DSR'!D50 -> Pcs | E14: ='P1-DSR'!E50 -> 8 | K14: FISHER S6 | L14: Pcs | M14: =SUMIF(B:B,K:K,E:E) -> 123.97778
B15: ='P1-DSR'!B51 -> SCREW 8X3 | C15: ='P1-DSR'!C51 -> 0 | D15: ='P1-DSR'!D51 -> Pcs | E15: ='P1-DSR'!E51 -> 27.133333 | K15: Foam Kusen - Dinding | L15: mm | M15: =SUMIF(B:B,K:K,C:C) -> 82000
B16: ='P1-DSR'!B52 -> FISHER S6 | C16: ='P1-DSR'!C52 -> 0 | D16: ='P1-DSR'!D52 -> Pcs | E16: ='P1-DSR'!E52 -> 27.133333 | K16: FS S/S 24" DKS | L16: Psg | M16: =SUMIF(B:B,K:K,E:E) -> 2
B17: ='P1-DSR'!B53 -> HOLE CAP | C17: ='P1-DSR'!C53 -> 0 | D17: ='P1-DSR'!D53 -> Pcs | E17: ='P1-DSR'!E53 -> 27.133333 | K17: Gasket New Mould - 002 (Karet Tatapan Jendela) Black | L17: mm | M17: =SUMIF(B:B,K:K,C:C) -> 9620
B18: ='P1-DSR'!B54 -> Foam Kusen - Dinding | C18: ='P1-DSR'!C54 -> 15960 | D18: ='P1-DSR'!D54 -> mm | E18: ='P1-DSR'!E54 -> - | K18: Gasket Sirip SF Black | L18: mm | M18: =SUMIF(B:B,K:K,C:C) -> 9620
B19: ='P1-DSR'!B55 -> SCREW 4X12 JF | C19: ='P1-DSR'!C55 -> 0 | D19: ='P1-DSR'!D55 -> Pcs | E19: ='P1-DSR'!E55 -> 24 | K19: HOLE CAP | L19: Pcs | M19: =SUMIF(B:B,K:K,E:E) -> 27.133333
B20: ='P1-DSR'!B56 -> SCREW 4X12 JP | C20: ='P1-DSR'!C56 -> 0 | D20: ='P1-DSR'!D56 -> Pcs | E20: ='P1-DSR'!E56 -> 12 | K20: MTS RL DL 8485 SSS DKS | L20: Set | M20: =SUMIF(B:B,K:K,E:E) -> 1
B21: ='P1-DSR'!B57 -> 0 | C21: ='P1-DSR'!C57 -> 0 | D21: ='P1-DSR'!D57 -> 0 | E21: ='P1-DSR'!E57 -> 0 | K21: PH DL446 32x600x400 SSS DKS | L21: Set | M21: =SUMIF(B:B,K:K,E:E) -> 2
B22: ='P1-DSR'!B58 -> Gasket | C22: ='P1-DSR'!C58 -> 0 | D22: ='P1-DSR'!D58 -> 0 | E22: ='P1-DSR'!E58 -> 0 | K22: SCREW 8X3 | L22: Pcs | M22: =SUMIF(B:B,K:K,E:E) -> 27.133333
B23: ='P1-DSR'!B59 -> 2K-22464 | C23: ='P1-DSR'!C59 -> 12460 | D23: ='P1-DSR'!D59 -> mm | E23: ='P1-DSR'!E59 -> - | K23: SCREW 8X3 JF | L23: Pcs | M23: =SUMIF(B:B,K:K,E:E) -> 96.844444
B24: ='P1-DSR'!B60 -> 0 | C24: ='P1-DSR'!C60 -> 0 | D24: ='P1-DSR'!D60 -> 0 | E24: ='P1-DSR'!E60 -> 0 | K24: SCREW 8X3/4 P | L24: Pcs | M24: =SUMIF(B:B,K:K,E:E) -> 8
B25: ='P1-DSR'!B61 -> Sealant | C25: ='P1-DSR'!C61 -> 0 | D25: ='P1-DSR'!D61 -> 0 | E25: ='P1-DSR'!E61 -> 0 | K25: SCREW 4X12 JF | L25: Pcs | M25: =SUMIF(B:B,K:K,E:E) -> 24
B26: ='P1-DSR'!B62 -> Sealant Kusen - Dinding | C26: ='P1-DSR'!C62 -> 15960 | D26: ='P1-DSR'!D62 -> mm | E26: ='P1-DSR'!E62 -> - | K26: SCREW 4X12 JP | L26: Pcs | M26: =SUMIF(B:B,K:K,E:E) -> 12
B27: ='P1-DSR'!B63 -> Sealant Kusen - Kaca | C27: ='P1-DSR'!C63 -> 30940 | D27: ='P1-DSR'!D63 -> mm | E27: ='P1-DSR'!E63 -> - | K27: SCREW 6 X 1/2 JP | L27: Pcs | M27: =SUMIF(B:B,K:K,E:E) -> 16
B28: ='J1-DSR'!B34 -> SEALER PAD | C28: ='J1-DSR'!C34 -> 0 | D28: ='J1-DSR'!D34 -> Pcs | E28: ='J1-DSR'!E34 -> 4 | K28: SCREW 8 X 3/4 JP | L28: Pcs | M28: =SUMIF(B:B,K:K,E:E) -> 60
B29: ='J1-DSR'!B35 -> SEALER PAD | C29: ='J1-DSR'!C35 -> 0 | D29: ='J1-DSR'!D35 -> Pcs | E29: ='J1-DSR'!E35 -> 2 | K29: Sealant Kusen - Dinding | L29: mm | M29: =SUMIF(B:B,K:K,C:C) -> 82000
B30: ='J1-DSR'!B36 -> 9K-30171 | C30: ='J1-DSR'!C36 -> 0 | D30: ='J1-DSR'!D36 -> Pcs | E30: ='J1-DSR'!E36 -> 23.866667 | K30: Sealant Kusen - Kaca | L30: mm | M30: =SUMIF(B:B,K:K,C:C) -> 145680
B31: ='J1-DSR'!B37 -> SCREW 8X3 JF | C31: ='J1-DSR'!C37 -> 0 | D31: ='J1-DSR'!D37 -> Pcs | E31: ='J1-DSR'!E37 -> 23.866667 | K31: SEALER PAD | L31: Pcs | M31: =SUMIF(B:B,K:K,E:E) -> 40
B32: ='J1-DSR'!B38 -> SCREW 8 X 3/4 JP | C32: ='J1-DSR'!C38 -> 0 | D32: ='J1-DSR'!D38 -> Pcs | E32: ='J1-DSR'!E38 -> 6
B33: ='J1-DSR'!B39 -> FISHER S6 | C33: ='J1-DSR'!C39 -> 0 | D33: ='J1-DSR'!D39 -> Pcs | E33: ='J1-DSR'!E39 -> 23.866667
B34: ='J1-DSR'!B40 -> SCREW 6 X 1/2 JP | C34: ='J1-DSR'!C40 -> 0 | D34: ='J1-DSR'!D40 -> Pcs | E34: ='J1-DSR'!E40 -> 0
B35: ='J1-DSR'!B41 -> 9K-11074 | C35: ='J1-DSR'!C41 -> 0 | D35: ='J1-DSR'!D41 -> Pcs | E35: ='J1-DSR'!E41 -> 23.866667
B36: ='J1-DSR'!B42 -> 9K-11072 | C36: ='J1-DSR'!C42 -> 0 | D36: ='J1-DSR'!D42 -> Pcs | E36: ='J1-DSR'!E42 -> 1
B37: ='J1-DSR'!B43 -> 9K-20602 | C37: ='J1-DSR'!C43 -> 0 | D37: ='J1-DSR'!D43 -> Pcs | E37: ='J1-DSR'!E43 -> 0
B38: ='J1-DSR'!B44 -> 2K-30630 | C38: ='J1-DSR'!C44 -> 0 | D38: ='J1-DSR'!D44 -> Set | E38: ='J1-DSR'!E44 -> 0
B39: ='J1-DSR'!B45 -> Foam Kusen - Dinding | C39: ='J1-DSR'!C45 -> 16200 | D39: ='J1-DSR'!D45 -> mm | E39: ='J1-DSR'!E45 -> -
B40: ='J1-DSR'!B46 -> 0 | C40: ='J1-DSR'!C46 -> 0 | D40: ='J1-DSR'!D46 -> 0 | E40: ='J1-DSR'!E46 -> 0
B41: ='J1-DSR'!B47 -> Gasket | C41: ='J1-DSR'!C47 -> 0 | D41: ='J1-DSR'!D47 -> 0 | E41: ='J1-DSR'!E47 -> 0
B42: ='J1-DSR'!B48 -> 0 | C42: ='J1-DSR'!C48 -> 0 | D42: ='J1-DSR'!D48 -> 0 | E42: ='J1-DSR'!E48 -> 0
...
